<?xml version="1.0"?>
<robot xmlns:xacro="http://www.ros.org/wiki/xacro">

    <xacro:include filename="colors.xacro" />
    <xacro:include filename="inertial_macros.xacro" />

    <link name="base_link">
    </link>

    <joint name="chassis_joint" type="fixed">
        <parent link="base_link"/>
        <child link="chassis"/>
        <origin xyz="-0.1 0 0"/>
    </joint>

    <xacro:property name="chassis_origin" value="0.15 0 0.075" />
    <xacro:property name="chassis_x" value="0.3" />
    <xacro:property name="chassis_y" value="0.3" />
    <xacro:property name="chassis_z" value="0.15" />
    <link name="chassis">
        <visual>
            <origin xyz="${chassis_origin}" rpy="0 0 0"/>
            <geometry>
                <box size="${chassis_x} ${chassis_y} ${chassis_z}"/>
            </geometry>
            <material name="white"/>
        </visual>
        <collision>
            <origin xyz="${chassis_origin}" rpy="0 0 0"/>
            <geometry>
                <box size="${chassis_x} ${chassis_y} ${chassis_z}"/>
            </geometry>
        </collision>
        <xacro:inertial_box mass="12" x="${chassis_x}" y="${chassis_y}" z="${chassis_z}">
            <origin xyz="${chassis_origin}" rpy="0 0 0"/>
        </xacro:inertial_box>
    </link>

    <gazebo reference="chassis">
        <material>Gazebo/White</material>
    </gazebo>


    <!-- LEFT WHEEL -->

    <xacro:property name="wheel_length" value="0.04" />
    <xacro:property name="wheel_radius" value="0.05" />
    
    <joint name="left_wheel_joint" type="continuous">
        <parent link="base_link"/>
        <child link="left_wheel"/>
        <origin xyz="0 0.175 0" rpy="-${pi/2} 0 0"/>
        <axis xyz="0 0 1"/>
    </joint>

    <link name="left_wheel">
        <visual>
            <geometry>
                <cylinder length="${wheel_length}" radius="${wheel_radius}" />
            </geometry>
            <material name="blue"/>
        </visual>
        <collision>
            <geometry>
                <cylinder length="${wheel_length}" radius="${wheel_radius}" />
            </geometry>
        </collision>
        <xacro:inertial_cylinder mass="1.0" length="${wheel_length}" radius="${wheel_radius}" >
            <origin xyz="0 0 0" rpy="0 0 0"/>
        </xacro:inertial_cylinder>
    </link>

    <gazebo reference="left_wheel">
        <material>Gazebo/Blue</material>
    </gazebo>


    <!-- RIGHT WHEEL -->

    <joint name="right_wheel_joint" type="continuous">
        <parent link="base_link"/>
        <child link="right_wheel"/>
        <origin xyz="0 -0.175 0" rpy="${pi/2} 0 0"/>
        <axis xyz="0 0 -1"/>
    </joint>

    <link name="right_wheel">
        <visual>
            <geometry>
                <cylinder length="${wheel_length}" radius="${wheel_radius}" />
            </geometry>
            <material name="blue"/>
        </visual>
        <collision>
            <geometry>
                <cylinder length="${wheel_length}" radius="${wheel_radius}" />
            </geometry>
        </collision>
        <xacro:inertial_cylinder mass="1.0" length="${wheel_length}" radius="${wheel_radius}" >
            <origin xyz="0 0 0" rpy="0 0 0"/>
        </xacro:inertial_cylinder>
    </link>

    <gazebo reference="right_wheel">
        <material>Gazebo/Blue</material>
    </gazebo>


    <!-- CASTER WHEEL -->

    <joint name="caster_wheel_joint" type="fixed">
        <parent link="chassis"/>
        <child link="caster_wheel"/>
        <origin xyz="0.24 0 0" rpy="0 0 0"/>
    </joint>

    <xacro:property name="caster_wheel_radius" value="0.05" />
    <link name="caster_wheel">
        <visual>
            <geometry>
                <sphere radius="${caster_wheel_radius}" />
            </geometry>
            <material name="black"/>
        </visual>
        <collision>
            <geometry>
                <sphere radius="${caster_wheel_radius}" />
            </geometry>
        </collision>
        <xacro:inertial_sphere mass="1.0" radius="${caster_wheel_radius}" >
            <origin xyz="0 0 0" rpy="0 0 0"/>
        </xacro:inertial_sphere>
    </link>

    <gazebo reference="caster_wheel">
        <material>Gazebo/Black</material>
        <mu1 value="0.001"/>
        <mu2 value="0.001"/>
    </gazebo>

</robot>